Workbook

Sheet Instruction Tab

Sheet Overall Summary
C3: Base Year | F3: ='Admin RO'!F22+'Sample RO I'!O22+'Sample RO II'!O22+'Sample RO III-Phase 1'!O22+'Sample RO III-Phase 2'!O22+'Sample RO IV'!O22+'Sample RO V'!O22+'Sample RO VI'!O22+'Sample RO VII'!O22+'Website maintenance'!O22+Training!O22+'Expert Group'!Z30+Workshop!Z30+'Contractor Travel'!Z86 -> 0
C4: Option Year 1 | F4: =F3*(1+Rates!$F$10) -> 0
C5: Option Year 2 | F5: =F4*(1+Rates!$F$10) -> 0
C6: Option Year 3 | F6: =F5*(1+Rates!$F$10) -> 0
C7: Option Year 4 | F7: =F6*(1+Rates!$F$10) -> 0
C8: Option Year 5 | F8: =F7*(1+Rates!$F$10) -> 0
C9: Option Year 6 | F9: =F8*(1+Rates!$F$10) -> 0
C10: Option Year 7 | F10: =F9*(1+Rates!$F$10) -> 0
C11: Option Year 8 | F11: =F10*(1+Rates!$F$10) -> 0
C12: Option Year 9 | F12: =F11*(1+Rates!$F$10) -> 0
C13: Option 2: Optional 6-month Extension | F13: =F12/2 -> 0
C15: Grand Total Base + All Options | F15: =SUM(F3:F14) -> 0

Sheet Rates
F5: Rates for Base Year
D6: Fringe
D7: Overhead
D8: G&A
D9: Fee
D10: Option Year escalation

Sheet Admin RO
A1: Protcol Outline for Administrative Support/Contract Administration
B3: Base Period per project costs
A4: Direct Labor | B4: hours | C4: x | D4: rate ($/hr) | F4: dollars
A5: Professional | C5: x | E5: = | F5: =B5*D5 -> 0
A6: Technical | C6: x | E6: = | F6: =B6*D6 -> 0
A7: Total hours and direct labor cost | B7: =SUM(B5:B6) -> 0 | F7: =SUM(F5:F6) -> 0
A9: with Fringe | F9: =F7*(1+Rates!F6) -> 0
A10: with Overhead | F10: =F9*(1+Rates!F7) -> 0
A11: Other Direct Costs
A12: Subcontracts
A13: Materials/Supplies
A14: Total Direct/Indirect | F14: =SUM(F10:F13) -> 0
A16: Gen & Administrative | F16: =F14*Rates!F8 -> 0
A17: Total with G&A | F17: =SUM(F14:F16) -> 0
A19: Fee | F19: =F17*Rates!F9 -> 0
A20: Total per project (base year 1) | F20: =SUM(F17:F19) -> 0
A21: Total Projects per year | E21: 1
A22: Grand Total | F22: =F20*E21 -> 0
A24: Assumptions
A34: Assumptions for this RO
A35: Use for activities associated with overall contract management and coordination, such as preparing monthly status report, monthly budget summary report, invoice and annual report, planning for attending periodic progress meetings with the Government, maintaining contract and research records, onboarding/offboarding Contractor staff, license fee, etc

Sheet Sample RO I
A1: Sample Research Outline I. Information and data extraction -Mining ICE for chemical information
B3: Base Period per project costs | I3: Option 1 - Additional LOE Option -- Base Period | O3: Total Base & Option 1
A4: Direct Labor | B4: hours | C4: x | D4: rate ($/hr) | I4: hours | J4: x | K4: rate ($/hr)
A5: Professional | C5: x | E5: = | F5: =B5*D5 -> 0 | J5: x | K5: =D5 -> 0 | L5: = | M5: =I5*K5 -> 0
A6: Technical | C6: x | E6: = | F6: =B6*D6 -> 0 | J6: x | K6: =D6 -> 0 | L6: = | M6: =I6*K6 -> 0
A7: Total hours and direct labor cost | B7: =SUM(B5:B6) -> 0 | F7: =SUM(F5:F6) -> 0 | I7: =SUM(I5:I6) -> 0 | M7: =SUM(M5:M6) -> 0
A9: with Fringe | F9: =F7*(1+Rates!$F$6) -> 0 | M9: =M7*(1+Rates!$F$6) -> 0
A10: with Overhead | F10: =F9*(1+Rates!$F$7) -> 0 | M10: =M9*(1+Rates!$F$7) -> 0
A11: Other Direct Costs | F11: 0 | M11: 0
A12: Subcontracts
A13: Materials/Supplies | F13: 0 | M13: 0
A14: Total Direct/Indirect | F14: =SUM(F10:F13) -> 0 | M14: =SUM(M10:M13) -> 0
A16: Gen & Administrative | F16: =F14*Rates!$F$8 -> 0 | M16: =M14*Rates!$F$8 -> 0
A17: Total with G&A | F17: =SUM(F14:F16) -> 0 | M17: =SUM(M14:M16) -> 0
A19: Fee | F19: =F17*Rates!$F$9 -> 0 | M19: =M17*Rates!$F$9 -> 0
A20: Total per project (base year 1) | F20: =SUM(F17:F19) -> 0 | M20: =SUM(M17:M19) -> 0
A21: Total Projects per year | E21: 10 | L21: 3
A22: Grand Total | F22: =F20*E21 -> 0 | M22: =M20*L21 -> 0 | O22: =F22+M22 -> 0
A24: Assumptions

Sheet Sample RO II
A1: Sample Research Outline II. Computational tool development - Pathway-Based Predictive Approaches for Cardiovascular Toxicity Assessment
B3: Base Period per project costs | I3: Option 1 -- Additional LOE Option -- Base Period | O3: Total Base & Option 1
A4: Direct Labor | B4: hours | C4: x | D4: rate ($/hr) | I4: hours | J4: x | K4: rate ($/hr)
A5: Professional | C5: x | E5: = | F5: =B5*D5 -> 0 | J5: x | K5: =D5 -> 0 | L5: = | M5: =I5*K5 -> 0
A6: Technical | C6: x | E6: = | F6: =B6*D6 -> 0 | J6: x | K6: =D6 -> 0 | L6: = | M6: =I6*K6 -> 0
A7: Total hours and direct labor cost | B7: =SUM(B5:B6) -> 0 | F7: =SUM(F5:F6) -> 0 | I7: =SUM(I5:I6) -> 0 | M7: =SUM(M5:M6) -> 0
A9: with Fringe | F9: =F7*(1+Rates!$F$6) -> 0 | M9: =M7*(1+Rates!$F$6) -> 0
A10: with Overhead | F10: =F9*(1+Rates!$F$7) -> 0 | M10: =M9*(1+Rates!$F$7) -> 0
A11: Other Direct Costs
A12: Subcontracts
A13: Materials/Supplies
A14: Total Direct/Indirect | F14: =SUM(F10:F13) -> 0 | M14: =SUM(M10:M13) -> 0
A16: Gen & Administrative | F16: =F14*Rates!$F$8 -> 0 | M16: =M14*Rates!$F$8 -> 0
A17: Total with G&A | F17: =SUM(F14:F16) -> 0 | M17: =SUM(M14:M16) -> 0
A19: Fee | F19: =F17*Rates!$F$9 -> 0 | M19: =M17*Rates!$F$9 -> 0
A20: Total per project (base year 1) | F20: =SUM(F17:F19) -> 0 | M20: =SUM(M17:M19) -> 0
A21: Total Projects per year | E21: 9 | L21: 2
A22: Grand Total | F22: =F20*E21 -> 0 | M22: =M20*L21 -> 0 | O22: =F22+M22 -> 0
A24: Assumptions

Sheet Sample RO III-Phase 1
A1: Sample Research Outline III. Interlaboratory study - phase I - iPSC-microglia Protocol development
B3: Base Period per project costs | I3: Option 1 -- Additional LOE Option Base Period | O3: Total Base & Option 1
A4: Direct Labor | B4: hours | C4: x | D4: rate ($/hr) | I4: hours | J4: x | K4: rate ($/hr)
A5: Professional | C5: x | E5: = | F5: =B5*D5 -> 0 | J5: x | K5: =D5 -> 0 | L5: = | M5: =I5*K5 -> 0
A6: Technical | C6: x | E6: = | F6: =B6*D6 -> 0 | J6: x | K6: =D6 -> 0 | L6: = | M6: =I6*K6 -> 0
A7: Total hours and direct labor cost | B7: =SUM(B5:B6) -> 0 | F7: =SUM(F5:F6) -> 0 | I7: =SUM(I5:I6) -> 0 | M7: =SUM(M5:M6) -> 0
A9: with Fringe | F9: =F7*(1+Rates!$F$6) -> 0 | M9: =M7*(1+Rates!$F$6) -> 0
A10: with Overhead | F10: =F9*(1+Rates!$F$7) -> 0 | M10: =M9*(1+Rates!$F$7) -> 0
A11: Other Direct Costs
A12: Subcontracts
A13: Materials/Supplies
A14: Total Direct/Indirect | F14: =SUM(F10:F13) -> 0 | M14: =SUM(M10:M13) -> 0
A16: Gen & Administrative | F16: =F14*Rates!$F$8 -> 0 | M16: =M14*Rates!$F$8 -> 0
A17: Total with G&A | F17: =SUM(F14:F16) -> 0 | M17: =SUM(M14:M16) -> 0
A19: Fee | F19: =F17*Rates!$F$9 -> 0 | M19: =M17*Rates!$F$9 -> 0
A20: Total per project (base year 1) | F20: =SUM(F17:F19) -> 0 | M20: =SUM(M17:M19) -> 0
A21: Total Projects per year | E21: 2 | L21: 0
A22: Grand Total | F22: =F20*E21 -> 0 | M22: =M20*L21 -> 0 | O22: =F22+M22 -> 0
A24: Assumptions

Sheet Sample RO III-Phase 2
A1: Sample Research Outline III. Interlaboratory study - phase II - iPSC-microglia Screening test
B3: Base Period per project costs | I3: Option 1 -- Additional LOE Option -- Base Period | O3: Total Base & Option 1
A4: Direct Labor | B4: hours | C4: x | D4: rate ($/hr) | I4: hours | J4: x | K4: rate ($/hr)
A5: Professional | C5: x | E5: = | F5: =B5*D5 -> 0 | J5: x | K5: =D5 -> 0 | L5: = | M5: =I5*K5 -> 0
A6: Technical | C6: x | E6: = | F6: =B6*D6 -> 0 | J6: x | K6: =D6 -> 0 | L6: = | M6: =I6*K6 -> 0
A7: Total hours and direct labor cost | B7: =SUM(B5:B6) -> 0 | F7: =SUM(F5:F6) -> 0 | I7: =SUM(I5:I6) -> 0 | M7: =SUM(M5:M6) -> 0
A9: with Fringe | F9: =F7*(1+Rates!$F$6) -> 0 | M9: =M7*(1+Rates!$F$6) -> 0
A10: with Overhead | F10: =F9*(1+Rates!$F$7) -> 0 | M10: =M9*(1+Rates!$F$7) -> 0
A11: Other Direct Costs
A12: Subcontracts
A13: Materials/Supplies
A14: Total Direct/Indirect | F14: =SUM(F10:F13) -> 0 | M14: =SUM(M10:M13) -> 0
A16: Gen & Administrative | F16: =F14*Rates!$F$8 -> 0 | M16: =M14*Rates!$F$8 -> 0
A17: Total with G&A | F17: =SUM(F14:F16) -> 0 | M17: =SUM(M14:M16) -> 0
A19: Fee | F19: =F17*Rates!$F$9 -> 0 | M19: =M17*Rates!$F$9 -> 0
A20: Total per project (base year 1) | F20: =SUM(F17:F19) -> 0 | M20: =SUM(M17:M19) -> 0
A21: Total Projects per year | E21: 2 | L21: 0
A22: Grand Total | F22: =F20*E21 -> 0 | M22: =M20*L21 -> 0 | O22: =F22+M22 -> 0
A24: Assumptions

Sheet Sample RO IV
A1: Sample Research Outline IV. Problem formulation - Development of NAM Sets for Evaluation of Emerging Contaminants
B3: Base Period per project costs | I3: Option 1 -- Additional LOE Option -- Base Period | O3: Total Base & Option 1
A4: Direct Labor | B4: hours | C4: x | D4: rate ($/hr) | I4: hours | J4: x | K4: rate ($/hr)
A5: Professional | C5: x | E5: = | F5: =B5*D5 -> 0 | J5: x | K5: =D5 -> 0 | L5: = | M5: =I5*K5 -> 0
A6: Technical | C6: x | E6: = | F6: =B6*D6 -> 0 | J6: x | K6: =D6 -> 0 | L6: = | M6: =I6*K6 -> 0
A7: Total hours and direct labor cost | B7: =SUM(B5:B6) -> 0 | F7: =SUM(F5:F6) -> 0 | I7: =SUM(I5:I6) -> 0 | M7: =SUM(M5:M6) -> 0
A9: with Fringe | F9: =F7*(1+Rates!$F$6) -> 0 | M9: =M7*(1+Rates!$F$6) -> 0
A10: with Overhead | F10: =F9*(1+Rates!$F$7) -> 0 | M10: =M9*(1+Rates!$F$7) -> 0
A11: Other Direct Costs | F11: 0 | M11: 0
A12: Subcontracts
A13: Materials/Supplies | F13: 0 | M13: 0
A14: Total Direct/Indirect | F14: =SUM(F10:F13) -> 0 | M14: =SUM(M10:M13) -> 0
A16: Gen & Administrative | F16: =F14*Rates!$F$8 -> 0 | M16: =M14*Rates!$F$8 -> 0
A17: Total with G&A | F17: =SUM(F14:F16) -> 0 | M17: =SUM(M14:M16) -> 0
A19: Fee | F19: =F17*Rates!$F$9 -> 0 | M19: =M17*Rates!$F$9 -> 0
A20: Total per project (base year 1) | F20: =SUM(F17:F19) -> 0 | M20: =SUM(M17:M19) -> 0
A21: Total Projects per year | E21: 6 | L21: 1
A22: Grand Total | F22: =F20*E21 -> 0 | M22: =M20*L21 -> 0 | O22: =F22+M22 -> 0
A24: Assumptions

Sheet Sample RO V
A1: Sample Research Outline V. Modeling - Structural- and Functional Pharmacokinetic-Based Prediction
B3: Base Period per project costs | I3: Option 1 -- Additional LOE Option -- Base Period | O3: Total Base & Option 1
A4: Direct Labor | B4: hours | C4: x | D4: rate ($/hr) | I4: hours | J4: x | K4: rate ($/hr)
A5: Professional | C5: x | E5: = | F5: =B5*D5 -> 0 | J5: x | K5: =D5 -> 0 | L5: = | M5: =I5*K5 -> 0
A6: Technical | C6: x | E6: = | F6: =B6*D6 -> 0 | J6: x | K6: =D6 -> 0 | L6: = | M6: =I6*K6 -> 0
A7: Total hours and direct labor cost | B7: =SUM(B5:B6) -> 0 | F7: =SUM(F5:F6) -> 0 | I7: =SUM(I5:I6) -> 0 | M7: =SUM(M5:M6) -> 0
A9: with Fringe | F9: =F7*(1+Rates!$F$6) -> 0 | M9: =M7*(1+Rates!$F$6) -> 0
A10: with Overhead | F10: =F9*(1+Rates!$F$7) -> 0 | M10: =M9*(1+Rates!$F$7) -> 0
A11: Other Direct Costs
A12: Subcontracts
A13: Materials/Supplies
A14: Total Direct/Indirect | F14: =SUM(F10:F13) -> 0 | M14: =SUM(M10:M13) -> 0
A16: Gen & Administrative | F16: =F14*Rates!$F$8 -> 0 | M16: =M14*Rates!$F$8 -> 0
A17: Total with G&A | F17: =SUM(F14:F16) -> 0 | M17: =SUM(M14:M16) -> 0
A19: Fee | F19: =F17*Rates!$F$9 -> 0 | M19: =M17*Rates!$F$9 -> 0
A20: Total per project (base year 1) | F20: =SUM(F17:F19) -> 0 | M20: =SUM(M17:M19) -> 0
A21: Total Projects per year | E21: 10 | L21: 2
A22: Grand Total | F22: =F20*E21 -> 0 | M22: =M20*L21 -> 0 | O22: =F22+M22 -> 0
A24: Assumptions

Sheet Sample RO VI
A1: Sample Research Outline VI. Database and Information Support - Development of AI-Powered Liver Fibrosis Prediction
B3: Base Period per project costs | I3: Option 1 -- Additional LOE Option -- Base Period | O3: Total Base & Option 1
A4: Direct Labor | B4: hours | C4: x | D4: rate ($/hr) | I4: hours | J4: x | K4: rate ($/hr)
A5: Professional | C5: x | E5: = | F5: =B5*D5 -> 0 | J5: x | K5: =D5 -> 0 | L5: = | M5: =I5*K5 -> 0
A6: Technical | C6: x | E6: = | F6: =B6*D6 -> 0 | J6: x | K6: =D6 -> 0 | L6: = | M6: =I6*K6 -> 0
A7: Total hours and direct labor cost | B7: =SUM(B5:B6) -> 0 | F7: =SUM(F5:F6) -> 0 | I7: =SUM(I5:I6) -> 0 | M7: =SUM(M5:M6) -> 0
A9: with Fringe | F9: =F7*(1+Rates!$F$6) -> 0 | M9: =M7*(1+Rates!$F$6) -> 0
A10: with Overhead | F10: =F9*(1+Rates!$F$7) -> 0 | M10: =M9*(1+Rates!$F$7) -> 0
A11: Other Direct Costs
A12: Subcontracts
A13: Materials/Supplies
A14: Total Direct/Indirect | F14: =SUM(F10:F13) -> 0 | M14: =SUM(M10:M13) -> 0
A16: Gen & Administrative | F16: =F14*Rates!$F$8 -> 0 | M16: =M14*Rates!$F$8 -> 0
A17: Total with G&A | F17: =SUM(F14:F16) -> 0 | M17: =SUM(M14:M16) -> 0
A19: Fee | F19: =F17*Rates!$F$9 -> 0 | M19: =M17*Rates!$F$9 -> 0
A20: Total per project (base year 1) | F20: =SUM(F17:F19) -> 0 | M20: =SUM(M17:M19) -> 0
A21: Total Projects per year | E21: 2 | L21: 1
A22: Grand Total | F22: =F20*E21 -> 0 | M22: =M20*L21 -> 0 | O22: =F22+M22 -> 0
A24: Assumptions

Sheet Sample RO VII
A1: Sample Research Outline VII. Meeting Support - Workshop
B3: Base Period per project costs | I3: Option 1 -- Additional LOE Option -- Base Period | O3: Total Base & Option 1
A4: Direct Labor | B4: hours | C4: x | D4: rate ($/hr) | I4: hours | J4: x | K4: rate ($/hr)
A5: Professional | C5: x | E5: = | F5: =B5*D5 -> 0 | J5: x | K5: =D5 -> 0 | L5: = | M5: =I5*K5 -> 0
A6: Technical | C6: x | E6: = | F6: =B6*D6 -> 0 | J6: x | K6: =D6 -> 0 | L6: = | M6: =I6*K6 -> 0
A7: Total hours and direct labor cost | B7: =SUM(B5:B6) -> 0 | F7: =SUM(F5:F6) -> 0 | I7: =SUM(I5:I6) -> 0 | M7: =SUM(M5:M6) -> 0
A9: with Fringe | F9: =F7*(1+Rates!$F$6) -> 0 | M9: =M7*(1+Rates!$F$6) -> 0
A10: with Overhead | F10: =F9*(1+Rates!$F$7) -> 0 | M10: =M9*(1+Rates!$F$7) -> 0
A11: Other Direct Costs
A12: Subcontracts
A13: Materials/Supplies
A14: Total Direct/Indirect | F14: =SUM(F10:F13) -> 0 | M14: =SUM(M10:M13) -> 0
A16: Gen & Administrative | F16: =F14*Rates!$F$8 -> 0 | M16: =M14*Rates!$F$8 -> 0
A17: Total with G&A | F17: =SUM(F14:F16) -> 0 | M17: =SUM(M14:M16) -> 0
A19: Fee | F19: =F17*Rates!$F$9 -> 0 | M19: =M17*Rates!$F$9 -> 0
A20: Total per project (base year 1) | F20: =SUM(F17:F19) -> 0 | M20: =SUM(M17:M19) -> 0
A21: Total Projects per year | E21: 27 | L21: 8
A22: Grand Total | F22: =F20*E21 -> 0 | M22: =M20*L21 -> 0 | O22: =F22+M22 -> 0
A24: Assumptions
A25: Twenty-seven (27) meeting events are expected for base peroid, including Specific Scientific Meetings, Expert Group meeting, Workshops and professional meetings. For costing purposes, the intension is to use the estimated labor hours for Workshop described in this RO to apply to other meeting support. Materials/Supplies for hosting Expert Group meetings and Workshops are expected to be more abundant and captured in "Expert Group" and "Workshop" tabs and not in this tab.

Sheet Website maintenance
A1: Website Maintenance
B3: Base Period per project costs | I3: Option 1 -- Additional LOE Option Base Period | O3: Total Base & Option 1
A4: Direct Labor | B4: hours | C4: x | D4: rate ($/hr) | I4: hours | J4: x | K4: rate ($/hr)
A5: Professional | C5: x | E5: = | F5: =B5*D5 -> 0 | J5: x | K5: =D5 -> 0 | L5: = | M5: =I5*K5 -> 0
A6: Technical | C6: x | E6: = | F6: =B6*D6 -> 0 | J6: x | K6: =D6 -> 0 | L6: = | M6: =I6*K6 -> 0
A7: Total hours and direct labor cost | B7: =SUM(B5:B6) -> 0 | F7: =SUM(F5:F6) -> 0 | I7: =SUM(I5:I6) -> 0 | M7: =SUM(M5:M6) -> 0
A9: with Fringe | F9: =F7*(1+Rates!$F$6) -> 0 | M9: =M7*(1+Rates!$F$6) -> 0
A10: with Overhead | F10: =F9*(1+Rates!$F$7) -> 0 | M10: =M9*(1+Rates!$F$7) -> 0
A11: Other Direct Costs
A12: Subcontracts
A13: Materials/Supplies
A14: Total Direct/Indirect | F14: =SUM(F10:F13) -> 0 | M14: =SUM(M10:M13) -> 0
A16: Gen & Administrative | F16: =F14*Rates!$F$8 -> 0 | M16: =M14*Rates!$F$8 -> 0
A17: Total with G&A | F17: =SUM(F14:F16) -> 0 | M17: =SUM(M14:M16) -> 0
A19: Fee | F19: =F17*Rates!$F$9 -> 0 | M19: =M17*Rates!$F$9 -> 0
A20: Total per project (base year 1) | F20: =SUM(F17:F19) -> 0 | M20: =SUM(M17:M19) -> 0
A21: Total Projects per year | E21: 3 | L21: 1
A22: Grand Total | F22: =F20*E21 -> 0 | M22: =M20*L21 -> 0 | O22: =F22+M22 -> 0
A24: Assumptions

Sheet Training
A1: Training support
B3: Base Period per project costs | I3: Option 1 -- Additional LOE Option -- Base Period | O3: Total Base & Option 1
A4: Direct Labor | B4: hours | C4: x | D4: rate ($/hr) | I4: hours | J4: x | K4: rate ($/hr)
A5: Professional | C5: x | E5: = | F5: =B5*D5 -> 0 | J5: x | K5: =D5 -> 0 | L5: = | M5: =I5*K5 -> 0
A6: Technical | C6: x | E6: = | F6: =B6*D6 -> 0 | J6: x | K6: =D6 -> 0 | L6: = | M6: =I6*K6 -> 0
A7: Total hours and direct labor cost | B7: =SUM(B5:B6) -> 0 | F7: =SUM(F5:F6) -> 0 | I7: =SUM(I5:I6) -> 0 | M7: =SUM(M5:M6) -> 0
A9: with Fringe | F9: =F7*(1+Rates!$F$6) -> 0 | M9: =M7*(1+Rates!$F$6) -> 0
A10: with Overhead | F10: =F9*(1+Rates!$F$7) -> 0 | M10: =M9*(1+Rates!$F$7) -> 0
A11: Other Direct Costs
A12: Subcontracts
A13: Materials/Supplies
A14: Total Direct/Indirect | F14: =SUM(F10:F13) -> 0 | M14: =SUM(M10:M13) -> 0
A16: Gen & Administrative | F16: =F14*Rates!$F$8 -> 0 | M16: =M14*Rates!$F$8 -> 0
A17: Total with G&A | F17: =SUM(F14:F16) -> 0 | M17: =SUM(M14:M16) -> 0
A19: Fee | F19: =F17*Rates!$F$9 -> 0 | M19: =M17*Rates!$F$9 -> 0
A20: Total per project (base year 1) | F20: =SUM(F17:F19) -> 0 | M20: =SUM(M17:M19) -> 0
A21: Total Projects per year | E21: 2 | L21: 1
A22: Grand Total | F22: =F20*E21 -> 0 | M22: =M20*L21 -> 0 | O22: =F22+M22 -> 0
A24: Assumptions

Sheet Expert Group
A1: Contract Other Direct Costs: Meeting material and Participant travel for Exper Group Meetings (4 travel days)
A2: Assumptions: 5 international participants, 10 domestic travelers; meeting held RTP; Government location; 2 day meeting + 2 travel day
F4: Base Period per project costs | P4: Option 1 -- Additional LOE Option -- Base Period | Z4: Total Base & Option 1
F5: Units | I5: Units | P5: Units | S5: Units
F6: $ | I6: # | L6: # | P6: $ | S6: # | V6: #
A7: 1 | B7: Airfare - International | G7: per person | H7: X | J7: persons | K7: x | M7: = | N7: =F7*I7*L7 -> 0 | Q7: per person | R7: X | T7: persons | U7: x | W7: = | X7: =P7*S7*V7 -> 0
A8: 2 | B8: Airfare - Domestic | G8: per person | H8: X | J8: people | K8: X | M8: = | N8: =F8*I8*L8 -> 0 | Q8: per person | R8: X | T8: people | U8: X | W8: = | X8: =P8*S8*V8 -> 0
A9: 3 | B9: Lodging (Durham, NC Gov't rate) | G9: per night | H9: X | J9: nights | K9: X | M9: people | N9: =F9*I9*L9 -> 0 | Q9: per night | R9: X | T9: nights | U9: X | W9: people | X9: =P9*S9*V9 -> 0
A10: 4 | B10: Per Diem and Incidental expenses | G10: per day | H10: X | J10: days | K10: X | M10: people | N10: =F10*I10*L10 -> 0 | Q10: per day | R10: X | T10: days | U10: X | W10: people | X10: =P10*S10*V10 -> 0
B11: Total | N11: =SUM(N7:N10) -> 0 | X11: =SUM(X7:X10) -> 0
B12: With Gen & Administrative | N12: =N11*(1+Rates!$F$8) -> 0 | X12: =X11*(1+Rates!$F$8) -> 0
B13: With Fee | N13: =N12*(1+Rates!$F$9) -> 0 | X13: =X12*(1+Rates!$F$9) -> 0
F14: TOTAL | N14: =N13 -> 0 | P14: TOTAL | X14: =X13 -> 0
A16: Miscelleneous
A17: 5 | B17: Miscelleneous (to cover airport parking, ground transportation, tolls, telephone) | G17: per day | H17: X | J17: days | K17: X | M17: people | N17: =F17*I17*L17 -> 0 | Q17: per day | R17: X | T17: days | U17: X | W17: people | X17: =P17*S17*V17 -> 0
A18: 6 | B18: Baggage ($30 each way) | K18: X | M18: people | N18: =F18*I18*L18 -> 0 | U18: X | W18: people | X18: =P18*S18*V18 -> 0
A19: 7 | B19: Honorarium | G19: per day | H19: X | J19: days | K19: X | M19: people | N19: =F19*I19*L19 -> 0 | Q19: per day | R19: X | T19: days | U19: X | W19: people | X19: =P19*S19*V19 -> 0
A20: 8 | B20: Equipment rental (computers, copier, printer) | G20: per day | H20: X | J20: days | K20: X | M20: = | N20: =F20*I20*L20 -> 0 | Q20: per day | R20: X | T20: days | U20: X | W20: = | X20: =P20*S20*V20 -> 0
A21: 9 | B21: Transcriptionist | G21: per day | H21: X | J21: days | K21: X | M21: = | N21: =F21*I21*L21 -> 0 | Q21: per day | R21: X | T21: days | U21: X | W21: = | X21: =P21*S21*V21 -> 0
A22: 10 | B22: Material and Supplies (paper, pens, name tags, etc.) | G22: per meeting | H22: x | J22: NA | K22: x | M22: = | N22: =F22*I22*L22 -> 0 | Q22: per meeting | R22: x | T22: NA | U22: x | W22: = | X22: =P22*S22*V22 -> 0
B23: Total | N23: =SUM(N17:N22) -> 0 | X23: =SUM(X17:X22) -> 0
B24: With Gen & Administrative | N24: =N23*(1+Rates!$F$8) -> 0 | X24: =X23*(1+Rates!$F$8) -> 0
B25: With Fee | N25: =N24*(1+Rates!$F$9) -> 0 | X25: =X24*(1+Rates!$F$9) -> 0
M26: TOTAL | N26: =SUM(N17:N22) -> 0 | W26: TOTAL | X26: =SUM(X17:X22) -> 0
F28: MEETING AND PARTICIPANT TRAVEL GRAND TOTAL | N28: =SUM(N14,N26) -> 0 | P28: MEETING AND PARTICIPANT TRAVEL GRAND TOTAL | X28: =SUM(X14,X26) -> 0
B30: Total Projects per year | M30: 2 | N30: =N28*M30 -> 0 | W30: 1 | X30: =X28*W30 -> 0 | Z30: =N30+X30 -> 0
A32: Assumptions

Sheet Workshop
A1: Contract Other Direct Costs: Meeting material and Participant travel for Workshop/Symposia/Seminar/Webinar (1 1/2 days) (3 travel days)
A2: For in-person meetings, 12 panel members will be invited
A3: Assumptions: 3 international, 9 domestic travelers; meeting held in DC metro area
F5: Base Period per project costs | P5: Option 1 -- Additional LOE Option -- Base Period | Z5: Total Base & Option 1
F6: Units | I6: Units | L6: Units | P6: Units | S6: Units | V6: Units
F7: $ | I7: # | L7: # | P7: $ | S7: # | V7: #
A8: 1 | B8: Airfare - International | G8: per person | H8: X | J8: people | K8: X | M8: = | N8: =F8*I8*L8 -> 0 | Q8: per person | R8: X | T8: people | U8: X | W8: = | X8: =P8*S8*V8 -> 0
A9: 2 | B9: Airfare - Domestic | G9: per person | H9: X | J9: people | K9: X | M9: = | N9: =F9*I9*L9 -> 0 | Q9: per person | R9: X | T9: people | U9: X | W9: = | X9: =P9*S9*V9 -> 0
A10: 3 | B10: Lodging (Washington, DC Gov't rate) | G10: per night | H10: X | J10: nights | K10: X | M10: = | N10: =F10*I10*L10 -> 0 | Q10: per night | R10: X | T10: nights | U10: X | W10: = | X10: =P10*S10*V10 -> 0
A11: 4 | B11: Per Diem and Incidental expenses | G11: per day | H11: X | J11: days | K11: X | M11: = | N11: =F11*I11*L11 -> 0 | Q11: per day | R11: X | T11: days | U11: X | W11: = | X11: =P11*S11*V11 -> 0
B12: Total | N12: =SUM(N8:N11) -> 0 | X12: =SUM(X8:X11) -> 0
B13: With Gen & Administrative | N13: =N12*(1+Rates!$F$8) -> 0 | X13: =X12*(1+Rates!$F$8) -> 0
B14: With Fee | N14: =N13*(1+Rates!$F$9) -> 0 | X14: =X13*(1+Rates!$F$9) -> 0
F15: TOTAL | N15: =N14 -> 0 | P15: TOTAL | X15: =X14 -> 0
A17: MISCELLENEOUS
A18: 5 | B18: Miscelleneous (to cover airport parking, ground transportation, tolls, telephone) | G18: per day | H18: X | J18: days | K18: X | M18: = | N18: =F18*I18*L18 -> 0 | Q18: per day | R18: X | T18: days | U18: X | W18: = | X18: =P18*S18*V18 -> 0
A19: 6 | B19: Baggage | K19: X | N19: =F19*L19 -> 0 | U19: X | X19: =P19*V19 -> 0
A20: 7 | B20: Equipment rental (computers, copier, printer) | G20: per day | H20: X | J20: days | K20: X | M20: = | N20: =F20*I20*L20 -> 0 | Q20: per day | R20: X | T20: days | U20: X | W20: = | X20: =P20*S20*V20 -> 0
A21: 8 | B21: Material and Supplies (paper, pens, name tags, etc.) | G21: per meeting | N21: =F21 -> 0 | Q21: per meeting | X21: =P21 -> 0
A22: 9 | B22: Webcast/teleconference costs for remote viewing | G22: per meeting | N22: =F22 -> 0 | Q22: per meeting | X22: =P22 -> 0
B23: Total | N23: =SUM(N18:N22) -> 0 | X23: =SUM(X18:X22) -> 0
B24: With Gen & Administrative | N24: =N23*(1+Rates!$F$8) -> 0 | X24: =X23*(1+Rates!$F$8) -> 0
B25: With Fee | N25: =N24*(1+Rates!$F$9) -> 0 | X25: =X24*(1+Rates!$F$9) -> 0
F26: TOTAL | N26: =N25 -> 0 | P26: TOTAL | X26: =X25 -> 0
F28: MEETING AND PARTICIPANT TRAVEL GRAND TOTAL | N28: =SUM(N26,N15) -> 0 | P28: MEETING AND PARTICIPANT TRAVEL GRAND TOTAL | X28: =SUM(X26,X15) -> 0
B30: Total Projects per year | M30: 3 | N30: =N28*M30 -> 0 | W30: 1 | X30: =X28*W30 -> 0 | Z30: =N30+X30 -> 0
A32: Assumptions

Sheet Contractor Travel
A1: Contract Other Direct Costs: Contractor Travel
A2: Assumptions: Specific Scientific Meeting, Expert Group, and Workshops/Symposium in-person meetings held in DC metro area; locations of SOT and World Congress shall be based on 2023 meetings.
F4: Base Period per trip costs | P4: Option 1 -- Additional LOE Option -- Base Period | Z4: Total Base & Option 1
F5: Units | I5: Units | L5: Units | P5: Units | S5: Units | V5: Units
A6: 1 | B6: Specific Scientific Meeting | F6: $ | I6: # | L6: # | N6: $ | P6: $ | S6: # | V6: # | X6: $
B7: Airfare | G7: per person | H7: X | J7: persons | N7: =F7*I7 -> 0 | Q7: per person | R7: X | T7: persons | X7: =P7*S7 -> 0
B8: Lodging | G8: per person | H8: X | J8: persons | K8: X | M8: nights | N8: =F8*I8*L8 -> 0 | Q8: per person | R8: X | T8: persons | U8: X | W8: nights | X8: =P8*S8*V8 -> 0
B9: Per diem | G9: per person | H9: X | J9: persons | K9: X | M9: day | N9: =F9*I9*L9 -> 0 | Q9: per person | R9: X | T9: persons | U9: X | W9: day | X9: =P9*S9*V9 -> 0
B10: Miscelleneous
B11: Miscelleneous (to cover airport parking, ground transportation, tolls, telephone) | G11: per day | H11: X | J11: people | K11: X | M11: day | N11: =F11*I11*L11 -> 0 | Q11: per day | R11: X | T11: people | U11: X | W11: day | X11: =P11*S11*V11 -> 0
B12: Baggage | H12: X | J12: people | N12: =F12*I12 -> 0 | R12: X | T12: people | X12: =P12*S12 -> 0
B13: Total | N13: =SUM(N7:N12) -> 0 | X13: =SUM(X7:X12) -> 0
B14: With Gen & Administrative | N14: =N13*(1+Rates!$F$8) -> 0 | X14: =X13*(1+Rates!$F$8) -> 0
B15: With Fee | N15: =N14*(1+Rates!$F$9) -> 0 | X15: =X14*(1+Rates!$F$9) -> 0
F16: ICCVAM MEETING GRAND TOTAL | N16: =N15 -> 0 | P16: ICCVAM MEETING GRAND TOTAL | X16: =X15 -> 0
B17: Total Projects per year | M17: 2 | N17: =N16*M17 -> 0 | W17: 0 | X17: =X16*W17 -> 0 | Z17: =N17+X17 -> 0
F19: Units | I19: Units | L19: Units | P19: Units | S19: Units | V19: Units
A20: 2 | B20: Expert group Meeting (assume held in Washington, DC)
B21: Airfare | G21: per person | H21: X | J21: persons | N21: =F21*I21 -> 0 | Q21: per person | R21: X | T21: persons | X21: =P21*S21 -> 0
B22: Lodging | G22: per person | H22: X | J22: persons | K22: X | M22: nights | N22: =F22*I22*L22 -> 0 | Q22: per person | R22: X | T22: persons | U22: X | W22: nights | X22: =P22*S22*V22 -> 0
B23: Per diem | G23: per person | H23: X | J23: persons | K23: X | M23: days | N23: =F23*I23*L23 -> 0 | Q23: per person | R23: X | T23: persons | U23: X | W23: days | X23: =P23*S23*V23 -> 0
B24: Miscelleneous
B25: Miscelleneous (to cover airport parking, ground transportation, tolls, telephone) | G25: per day | H25: X | J25: persons | K25: X | M25: days | N25: =F25*I25*L25 -> 0 | Q25: per day | R25: X | T25: persons | U25: X | W25: days | X25: =P25*S25*V25 -> 0
B26: Baggage | H26: X | J26: persons | N26: =F26*I26 -> 0 | R26: X | T26: persons | X26: =P26*S26 -> 0
B27: Total | N27: =SUM(N21:N26) -> 0 | X27: =SUM(X21:X26) -> 0
B28: With Gen & Administrative | N28: =N27*(1+Rates!$F$8) -> 0 | X28: =X27*(1+Rates!$F$8) -> 0
B29: With Fee | N29: =N28*(1+Rates!$F$9) -> 0 | X29: =X28*(1+Rates!$F$9) -> 0
F30: EXPERT GROUP MEETING GRAND TOTAL | N30: =N29 -> 0 | P30: EXPERT GROUP MEETING GRAND TOTAL | X30: =X29 -> 0
B31: Total Projects per year | M31: 2 | N31: =N30*M31 -> 0 | W31: 1 | X31: =X30*W31 -> 0 | Z31: =N31+X31 -> 0
F33: Units | I33: Units | L33: Units | P33: Units | S33: Units | V33: Units
A34: 3 | B34: Workshop/Symposium
B35: Airfare | G35: per person | H35: X | J35: persons | N35: =F35*I35 -> 0 | Q35: per person | R35: X | T35: persons | X35: =P35*S35 -> 0
B36: Lodging | G36: per person | H36: X | J36: persons | K36: X | M36: nights | N36: =F36*I36*L36 -> 0 | Q36: per person | R36: X | T36: persons | U36: X | W36: nights | X36: =P36*S36*V36 -> 0
B37: Per diem | G37: per person | H37: X | J37: persons | K37: X | M37: days | N37: =F37*I37*L37 -> 0 | Q37: per person | R37: X | T37: persons | U37: X | W37: days | X37: =P37*S37*V37 -> 0
B38: Miscelleneous
B39: Miscelleneous (to cover airport parking, ground transportation, tolls, telephone) | G39: per day | H39: X | J39: people | K39: X | M39: days | N39: =F39*I39*L39 -> 0 | Q39: per day | R39: X | T39: people | U39: X | W39: days | X39: =P39*S39*V39 -> 0
B40: Baggage | H40: X | J40: persons | N40: =F40*I40 -> 0 | R40: X | T40: persons | X40: =P40*S40 -> 0
B41: Total | N41: =SUM(N35:N40) -> 0 | X41: =SUM(X35:X40) -> 0
B42: With Gen & Administrative | N42: =N41*(1+Rates!$F$8) -> 0 | X42: =X41*(1+Rates!$F$8) -> 0
B43: With Fee | N43: =N42*(1+Rates!$F$9) -> 0 | X43: =X42*(1+Rates!$F$9) -> 0
...

Sheet SUMMARY
A1: All activities (Research Outlines and non-Research Outlines) Cost and Hours per project
B2: Cost Yr 1 | C2: Hrs | D2: Cost/hr
A3: Admin RO. | B3: ='Admin RO'!F20 -> 0 | D3: =B3/C3 -> #DIV/0!
A4: RO.I. Information and data extraction -Mining ICE for chemical information | B4: ='Sample RO I'!F20 -> 0 | D4: =B4/C4 -> #DIV/0!
A5: RO.II. Computational tool development - Pathway-Based Predictive Approaches for Cardiovascular Toxicity Assessment | B5: ='Sample RO II'!F20 -> 0 | D5: =B5/C5 -> #DIV/0!
A6: RO.III. Interlaboratory study - phase I - iPSC-microglia Protocol development | B6: ='Sample RO III-Phase 1'!F20 -> 0 | D6: =B6/C6 -> #DIV/0!
A7: RO.III. Interlaboratory study - phase II - iPSC-microglia Screening test | B7: ='Sample RO III-Phase 2'!F20 -> 0 | D7: =B7/C7 -> #DIV/0!
A8: RO.IV. Problem formulation - Development of NAM Sets for Evaluation of Emerging Contaminants | B8: ='Sample RO IV'!F20 -> 0 | D8: =B8/C8 -> #DIV/0!
A9: RO.V. Modeling - Structural- and Functional Pharmacokinetic-Based Prediction | B9: ='Sample RO V'!F20 -> 0 | D9: =B9/C9 -> #DIV/0!
A10: RO.VI. Database and Information Support - AI-powered tool development | B10: ='Sample RO VI'!F20 -> 0 | D10: =B10/C10 -> #DIV/0!
A11: RO.VII. Meeting Support - Workshop | B11: ='Sample RO VII'!F20 -> 0 | D11: =B11/C11 -> #DIV/0!
A12: Website Maintenance | B12: ='Website maintenance'!F20 -> 0 | D12: =B12/C12 -> #DIV/0!
A13: Training Support | B13: =Training!F20 -> 0 | D13: =B13/C13 -> #DIV/0!
A14: NOTE: For Fields C3:C13, include subcontract hours
A15: Cost by activites (per project)
B16: Start Yr 1 | C16: Start Yr 2 | D16: Start Yr 3 | E16: Start Yr 4 | F16: Start Yr 5 | G16: Start Yr 6 | H16: Start Yr 7 | I16: Start Yr 8 | J16: Start Yr 9 | K16: Start Yr 10
A17: Admin RO. | B17: =B3 -> 0 | C17: =B17*(1+Rates!$F$10) -> 0 | D17: =C17*(1+Rates!$F$10) -> 0 | E17: =D17*(1+Rates!$F$10) -> 0 | F17: =E17*(1+Rates!$F$10) -> 0 | G17: =F17*(1+Rates!$F$10) -> 0 | H17: =G17*(1+Rates!$F$10) -> 0 | I17: =H17*(1+Rates!$F$10) -> 0 | J17: =I17*(1+Rates!$F$10) -> 0 | K17: =J17*(1+Rates!$F$10) -> 0
A18: RO.I. Information and data extraction -Mining ICE for chemical information | B18: =B4 -> 0 | C18: =B18*(1+Rates!$F$10) -> 0 | D18: =C18*(1+Rates!$F$10) -> 0 | E18: =D18*(1+Rates!$F$10) -> 0 | F18: =E18*(1+Rates!$F$10) -> 0 | G18: =F18*(1+Rates!$F$10) -> 0 | H18: =G18*(1+Rates!$F$10) -> 0 | I18: =H18*(1+Rates!$F$10) -> 0 | J18: =I18*(1+Rates!$F$10) -> 0 | K18: =J18*(1+Rates!$F$10) -> 0
A19: RO.II. Computational tool development - Pathway-Based Predictive Approaches for Cardiovascular Toxicity Assessment | B19: =B5 -> 0 | C19: =B19*(1+Rates!$F$10) -> 0 | D19: =C19*(1+Rates!$F$10) -> 0 | E19: =D19*(1+Rates!$F$10) -> 0 | F19: =E19*(1+Rates!$F$10) -> 0 | G19: =F19*(1+Rates!$F$10) -> 0 | H19: =G19*(1+Rates!$F$10) -> 0 | I19: =H19*(1+Rates!$F$10) -> 0 | J19: =I19*(1+Rates!$F$10) -> 0 | K19: =J19*(1+Rates!$F$10) -> 0
A20: RO.III. Interlaboratory study - phase I - iPSC-microglia Protocol development | B20: =B6 -> 0 | C20: =B20*(1+Rates!$F$10) -> 0 | D20: =C20*(1+Rates!$F$10) -> 0 | E20: =D20*(1+Rates!$F$10) -> 0 | F20: =E20*(1+Rates!$F$10) -> 0 | G20: =F20*(1+Rates!$F$10) -> 0 | H20: =G20*(1+Rates!$F$10) -> 0 | I20: =H20*(1+Rates!$F$10) -> 0 | J20: =I20*(1+Rates!$F$10) -> 0 | K20: =J20*(1+Rates!$F$10) -> 0
A21: RO.III. Interlaboratory study - phase II - iPSC-microglia Screening test | B21: =B7 -> 0 | C21: =B21*(1+Rates!$F$10) -> 0 | D21: =C21*(1+Rates!$F$10) -> 0 | E21: =D21*(1+Rates!$F$10) -> 0 | F21: =E21*(1+Rates!$F$10) -> 0 | G21: =F21*(1+Rates!$F$10) -> 0 | H21: =G21*(1+Rates!$F$10) -> 0 | I21: =H21*(1+Rates!$F$10) -> 0 | J21: =I21*(1+Rates!$F$10) -> 0 | K21: =J21*(1+Rates!$F$10) -> 0
A22: RO.IV. Problem formulation - Development of NAM Sets for Evaluation of Emerging Contaminants | B22: =B8 -> 0 | C22: =B22*(1+Rates!$F$10) -> 0 | D22: =C22*(1+Rates!$F$10) -> 0 | E22: =D22*(1+Rates!$F$10) -> 0 | F22: =E22*(1+Rates!$F$10) -> 0 | G22: =F22*(1+Rates!$F$10) -> 0 | H22: =G22*(1+Rates!$F$10) -> 0 | I22: =H22*(1+Rates!$F$10) -> 0 | J22: =I22*(1+Rates!$F$10) -> 0 | K22: =J22*(1+Rates!$F$10) -> 0
A23: RO.V. Modeling - Structural- and Functional Pharmacokinetic-Based Prediction | B23: =B9 -> 0 | C23: =B23*(1+Rates!$F$10) -> 0 | D23: =C23*(1+Rates!$F$10) -> 0 | E23: =D23*(1+Rates!$F$10) -> 0 | F23: =E23*(1+Rates!$F$10) -> 0 | G23: =F23*(1+Rates!$F$10) -> 0 | H23: =G23*(1+Rates!$F$10) -> 0 | I23: =H23*(1+Rates!$F$10) -> 0 | J23: =I23*(1+Rates!$F$10) -> 0 | K23: =J23*(1+Rates!$F$10) -> 0
A24: RO.VI. Database and Information Support - AI-powered tool development | B24: =B10 -> 0 | C24: =B24*(1+Rates!$F$10) -> 0 | D24: =C24*(1+Rates!$F$10) -> 0 | E24: =D24*(1+Rates!$F$10) -> 0 | F24: =E24*(1+Rates!$F$10) -> 0 | G24: =F24*(1+Rates!$F$10) -> 0 | H24: =G24*(1+Rates!$F$10) -> 0 | I24: =H24*(1+Rates!$F$10) -> 0 | J24: =I24*(1+Rates!$F$10) -> 0 | K24: =J24*(1+Rates!$F$10) -> 0
A25: RO.VII. Meeting Support - Workshop | B25: =B11 -> 0 | C25: =B25*(1+Rates!$F$10) -> 0 | D25: =C25*(1+Rates!$F$10) -> 0 | E25: =D25*(1+Rates!$F$10) -> 0 | F25: =E25*(1+Rates!$F$10) -> 0 | G25: =F25*(1+Rates!$F$10) -> 0 | H25: =G25*(1+Rates!$F$10) -> 0 | I25: =H25*(1+Rates!$F$10) -> 0 | J25: =I25*(1+Rates!$F$10) -> 0 | K25: =J25*(1+Rates!$F$10) -> 0
A26: Website Maintenance | B26: =B12 -> 0 | C26: =B26*(1+Rates!$F$10) -> 0 | D26: =C26*(1+Rates!$F$10) -> 0 | E26: =D26*(1+Rates!$F$10) -> 0 | F26: =E26*(1+Rates!$F$10) -> 0 | G26: =F26*(1+Rates!$F$10) -> 0 | H26: =G26*(1+Rates!$F$10) -> 0 | I26: =H26*(1+Rates!$F$10) -> 0 | J26: =I26*(1+Rates!$F$10) -> 0 | K26: =J26*(1+Rates!$F$10) -> 0
A27: Training Support | B27: =B13 -> 0 | C27: =B27*(1+Rates!$F$10) -> 0 | D27: =C27*(1+Rates!$F$10) -> 0 | E27: =D27*(1+Rates!$F$10) -> 0 | F27: =E27*(1+Rates!$F$10) -> 0 | G27: =F27*(1+Rates!$F$10) -> 0 | H27: =G27*(1+Rates!$F$10) -> 0 | I27: =H27*(1+Rates!$F$10) -> 0 | J27: =I27*(1+Rates!$F$10) -> 0 | K27: =J27*(1+Rates!$F$10) -> 0
A30: Total Cost for cumulative number of projects anticipated | O30: Cost Summary
A31: Base and Option Years | B31: Start Yr 1 | C31: Start Yr 2 | D31: Start Yr 3 | E31: Start Yr 4 | F31: Start Yr 5 | G31: Start Yr 6 | H31: Start Yr 7 | I31: Start Yr 8 | J31: Start Yr 9 | K31: Start Yr 10 | L31: Total | O31: Base Total | P31: =L45 -> 0
A32: Admin RO. | B32: =B17*1 -> 0 | C32: =C17*1 -> 0 | D32: =D17*1 -> 0 | E32: =E17*1 -> 0 | F32: =F17*1 -> 0 | G32: =G17*1 -> 0 | H32: =H17*1 -> 0 | I32: =I17*1 -> 0 | ... K32: =K17*1 -> 0 | L32: =SUM(B32:K32) -> 0 | O32: Base + Option 1 Total | P32: =SUM(P31+L62) -> 0
A33: RO.I. Information and data extraction -Mining ICE for chemical information | B33: =B18*10 -> 0 | C33: =C18*10 -> 0 | D33: =D18*10 -> 0 | E33: =E18*10 -> 0 | F33: =F18*10 -> 0 | G33: =G18*10 -> 0 | H33: =H18*10 -> 0 | I33: =I18*10 -> 0 | ... K33: =K18*10 -> 0 | L33: =SUM(B33:K33) -> 0 | O33: Base + Option 1 + Option 2 Total | P33: =SUM(P32+M62) -> 0
A34: RO.II. Computational tool development - Pathway-Based Predictive Approaches for Cardiovascular Toxicity Assessment | B34: =B19*9 -> 0 | C34: =C19*9 -> 0 | D34: =D19*9 -> 0 | E34: =E19*9 -> 0 | F34: =F19*9 -> 0 | G34: =G19*9 -> 0 | H34: =H19*9 -> 0 | I34: =I19*9 -> 0 | ... K34: =K19*9 -> 0 | L34: =SUM(B34:K34) -> 0
A35: RO.III. Interlaboratory study - phase I - iPSC-microglia Protocol development | B35: =B20*2 -> 0 | C35: =C20*2 -> 0 | D35: =D20*2 -> 0 | E35: =E20*2 -> 0 | F35: =F20*2 -> 0 | G35: =G20*2 -> 0 | H35: =H20*2 -> 0 | I35: =I20*2 -> 0 | ... K35: =K20*2 -> 0 | L35: =SUM(B35:K35) -> 0
A36: RO.III. Interlaboratory study - phase II - iPSC-microglia Screening test | B36: =B21*2 -> 0 | C36: =C21*2 -> 0 | D36: =D21*2 -> 0 | E36: =E21*2 -> 0 | F36: =F21*2 -> 0 | G36: =G21*2 -> 0 | H36: =H21*2 -> 0 | I36: =I21*2 -> 0 | ... K36: =K21*2 -> 0 | L36: =SUM(B36:K36) -> 0
A37: RO.IV. Problem formulation - Development of NAM Sets for Evaluation of Emerging Contaminants | B37: =B22*6 -> 0 | C37: =C22*6 -> 0 | D37: =D22*6 -> 0 | E37: =E22*6 -> 0 | F37: =F22*6 -> 0 | G37: =G22*6 -> 0 | H37: =H22*6 -> 0 | I37: =I22*6 -> 0 | ... K37: =K22*6 -> 0 | L37: =SUM(B37:K37) -> 0
A38: RO.V. Modeling - Structural- and Functional Pharmacokinetic-Based Prediction | B38: =B23*10 -> 0 | C38: =C23*10 -> 0 | D38: =D23*10 -> 0 | E38: =E23*10 -> 0 | F38: =F23*10 -> 0 | G38: =G23*10 -> 0 | H38: =H23*10 -> 0 | I38: =I23*10 -> 0 | ... K38: =K23*10 -> 0 | L38: =SUM(B38:K38) -> 0
A39: RO.VI. Database and Information Support - AI-powered tool development | B39: =B24*2 -> 0 | C39: =C24*2 -> 0 | D39: =D24*2 -> 0 | E39: =E24*2 -> 0 | F39: =F24*2 -> 0 | G39: =G24*2 -> 0 | H39: =H24*2 -> 0 | I39: =I24*2 -> 0 | ... K39: =K24*2 -> 0 | L39: =SUM(B39:K39) -> 0
A40: RO.VII. Meeting Support - Workshop | B40: =B25*27 -> 0 | C40: =C25*27 -> 0 | D40: =D25*27 -> 0 | E40: =E25*27 -> 0 | F40: =F25*27 -> 0 | G40: =G25*27 -> 0 | H40: =H25*27 -> 0 | I40: =I25*27 -> 0 | ... K40: =K25*27 -> 0 | L40: =SUM(B40:K40) -> 0
A41: Website Maintenance | B41: =B26*3 -> 0 | C41: =C26*3 -> 0 | D41: =D26*3 -> 0 | E41: =E26*3 -> 0 | F41: =F26*3 -> 0 | G41: =G26*3 -> 0 | H41: =H26*3 -> 0 | I41: =I26*3 -> 0 | ... K41: =K26*3 -> 0 | L41: =SUM(B41:K41) -> 0
A42: Training Support | B42: =B27*2 -> 0 | C42: =C27*2 -> 0 | D42: =D27*2 -> 0 | E42: =E27*2 -> 0 | F42: =F27*2 -> 0 | G42: =G27*2 -> 0 | H42: =H27*2 -> 0 | I42: =I27*2 -> 0 | ... K42: =K27*2 -> 0 | L42: =SUM(B42:K42) -> 0
...

Sheet Exec Summary
B1: Base/Option Years | E1: Option 1 -- Additional LOE Options (start year 1)
A2: Direct Labor | B2: Hours | D2: Total | E2: Hours | G2: Total
A3: Professional | B3: =SUM('Admin RO'!B5,('Sample RO I'!B5*10),('Sample RO II'!B5*9),('Sample RO III-Phase 1'!B5*2),('Sample RO III-Phase 2'!B5*2),('Sample RO IV'!B5*6),('Sample RO V'!B5*10),('Sample RO VI'!B5*2),('Sample RO VII'!B5*27),('Website maintenance'!B5*3),(Training!B5*2)) -> 0 | D3: =SUM('Admin RO'!F5,('Sample RO I'!F5*10),('Sample RO II'!F5*9),('Sample RO III-Phase 1'!F5*2),('Sample RO III-Phase 2'!F5*2),('Sample RO IV'!F5*6),('Sample RO V'!F5*10),('Sample RO VI'!F5*2),('Sample RO VII'!F5*27),('Website maintenance'!F5*3),(Training!F5*2)) -> 0 | E3: =SUM(('Sample RO I'!B5*3),('Sample RO II'!B5*2),('Sample RO III-Phase 1'!B5*0),('Sample RO III-Phase 2'!B5*0),('Sample RO IV'!B5*1),('Sample RO V'!B5*2),('Sample RO VI'!B5*1),('Sample RO VII'!B5*8),('Website maintenance'!B5*1),(Training!B5*1)) -> 0 | G3: =SUM(('Sample RO I'!M5*3),('Sample RO II'!M5*2),('Sample RO III-Phase 1'!IM5*0),('Sample RO III-Phase 2'!M5*0),('Sample RO IV'!M5*1),('Sample RO V'!M5*2),('Sample RO VI'!M5*1),('Sample RO VII'!M5*8),('Website maintenance'!M5*1),(Training!M5*1)) -> 0
A4: Technical | B4: =SUM('Admin RO'!B6,('Sample RO I'!B6*10),('Sample RO II'!B6*9),('Sample RO III-Phase 1'!B6*2),('Sample RO III-Phase 2'!B6*2),('Sample RO IV'!B6*6),('Sample RO V'!B6*10),('Sample RO VI'!B6*2),('Sample RO VII'!B6*27),('Website maintenance'!B6*3),(Training!B6*2)) -> 0 | D4: =SUM('Admin RO'!F6,('Sample RO I'!F6*10),('Sample RO II'!F6*9),('Sample RO III-Phase 1'!F6*2),('Sample RO III-Phase 2'!F6*2),('Sample RO IV'!F6*6),('Sample RO V'!F6*10),('Sample RO VI'!F6*2),('Sample RO VII'!F6*27),('Website maintenance'!F6*3),(Training!F6*2)) -> 0 | E4: =SUM(,('Sample RO I'!B6*3),('Sample RO II'!B6*2),('Sample RO III-Phase 1'!B6*0),('Sample RO III-Phase 2'!B6*0),('Sample RO IV'!B6*1),('Sample RO V'!B6*2),('Sample RO VI'!B6*1),('Sample RO VII'!B6*8),('Website maintenance'!B6*1),(Training!B6*1)) -> 0 | G4: =SUM(('Sample RO I'!M6*3),('Sample RO II'!M6*2),('Sample RO III-Phase 1'!IM6*0),('Sample RO III-Phase 2'!M6*0),('Sample RO IV'!M6*1),('Sample RO V'!M6*2),('Sample RO VI'!M6*1),('Sample RO VII'!M6*8),('Website maintenance'!M6*1),(Training!M6*1)) -> 0
A5: Total Direct Labor | B5: =SUM(B3:B4) -> 0 | D5: =SUM(D3:D4) -> 0 | E5: =SUM(E3:E4) -> 0 | G5: =SUM(G3:G4) -> 0
A7: Fringe Benefits | D7: =D5*Rates!$F$6 -> 0 | G7: =G5*Rates!$F$6 -> 0
A8: Overhead | D8: =(D5+D7)*Rates!$F$7 -> 0 | G8: =(G5+G7)*Rates!$F$7 -> 0
A9: Other Direct Costs | D9: =SUM('Admin RO'!F11,('Sample RO I'!F11*10),('Sample RO II'!F11*9),('Sample RO III-Phase 1'!F11*2),('Sample RO III-Phase 2'!F11*2),('Sample RO IV'!F11*6),('Sample RO V'!F11*10),('Sample RO VI'!F11*2),('Sample RO VII'!F11*27),('Website maintenance'!F11*3),(Training!F11*2),((SUMMARY!B43)/(1+Rates!$F$9))/(1+Rates!$F$8),((SUMMARY!B44)/(1+Rates!$F$9))/(1+Rates!$F$8)) -> 0 | G9: =SUM(('Sample RO I'!M11*3),('Sample RO II'!M11*2),('Sample RO III-Phase 1'!M11*0),('Sample RO III-Phase 2'!M11*0),('Sample RO IV'!M11*1),('Sample RO V'!M11*2),('Sample RO VI'!M11*1),('Sample RO VII'!M11*8),('Website maintenance'!M11*1),(Training!M11*1),((SUMMARY!B60)/(1+Rates!$F$9))/(1+Rates!$F$8),((SUMMARY!B61)/(1+Rates!$F$9))/(1+Rates!$F$8)) -> 0
A10: Subcontracts | D10: =SUM('Admin RO'!F12,('Sample RO I'!F12*10),('Sample RO II'!F12*9),('Sample RO III-Phase 1'!F12*2),('Sample RO III-Phase 2'!F12*2),('Sample RO IV'!F12*6),('Sample RO V'!F12*10),('Sample RO VI'!F12*2),('Sample RO VII'!F12*27),('Website maintenance'!F12*3),(Training!F12*2)) -> 0 | G10: =SUM(('Sample RO I'!M12*3),('Sample RO II'!M12*2),('Sample RO III-Phase 1'!M12*0),('Sample RO III-Phase 2'!M12*0),('Sample RO IV'!M12*1),('Sample RO V'!M12*2),('Sample RO VI'!M12*1),('Sample RO VII'!M12*8),('Website maintenance'!M12*1),(Training!M12*1)) -> 0
A11: Materials/Supplies | D11: =SUM('Admin RO'!F13,('Sample RO I'!F13*10),('Sample RO II'!F13*9),('Sample RO III-Phase 1'!F13*2),('Sample RO III-Phase 2'!F13*2),('Sample RO IV'!F13*6),('Sample RO V'!F13*10),('Sample RO VI'!F13*2),('Sample RO VII'!F13*27),('Website maintenance'!F13*3),(Training!F13*2)) -> 0 | G11: =SUM(('Sample RO I'!F13*3),('Sample RO II'!F13*2),('Sample RO III-Phase 1'!F13*0),('Sample RO III-Phase 2'!F13*0),('Sample RO IV'!F13*1),('Sample RO V'!F13*2),('Sample RO VI'!F13*1),('Sample RO VII'!F13*8),('Website maintenance'!F13*1),(Training!F13*1)) -> 0
A12: Total Direct/Indirect | D12: =D5+SUM(D7:D11) -> 0 | G12: =G5+SUM(G7:G11) -> 0
A14: Gen & Administrative | D14: =D12*Rates!$F$8 -> 0 | G14: =G12*Rates!$F$8 -> 0
A15: Total with G&A | D15: =SUM(D12,D14) -> 0 | G15: =SUM(G12,G14) -> 0
A17: Fee | D17: =D15*Rates!$F$9 -> 0 | G17: =G15*Rates!$F$9 -> 0
A18: Total (base year 1) | D18: =SUM(D15,D17) -> 0 | G18: =SUM(G15,G17) -> 0
A21: Base Year | D21: =D18 -> 0 | G21: =G18 -> 0
A22: Option Year 1 | D22: =D21*(1+Rates!$F$10) -> 0 | G22: =G21*(1+Rates!$F$10) -> 0
A23: Option Year 2 | D23: =D22*(1+Rates!$F$10) -> 0 | G23: =G22*(1+Rates!$F$10) -> 0
A24: Option Year 3 | D24: =D23*(1+Rates!$F$10) -> 0 | G24: =G23*(1+Rates!$F$10) -> 0
A25: Option Year 4 | D25: =D24*(1+Rates!$F$10) -> 0 | G25: =G24*(1+Rates!$F$10) -> 0
A26: Option Year 5 | D26: =D25*(1+Rates!$F$10) -> 0 | G26: =G25*(1+Rates!$F$10) -> 0
A27: Option Year 6 | D27: =D26*(1+Rates!$F$10) -> 0 | G27: =G26*(1+Rates!$F$10) -> 0
A28: Option Year 7 | D28: =D27*(1+Rates!$F$10) -> 0 | G28: =G27*(1+Rates!$F$10) -> 0
A29: Option Year 8 | D29: =D28*(1+Rates!$F$10) -> 0 | G29: =G28*(1+Rates!$F$10) -> 0
A30: Option Year 9 | D30: =D29*(1+Rates!$F$10) -> 0 | G30: =G29*(1+Rates!$F$10) -> 0
C31: Base/Option 1 Total | D31: =SUM(B21:D30) -> 0
C32: Option 1 Total | D32: =SUM(G21:G30) -> 0
C33: Option 2 | D33: =(D30+G30)/2 -> 0
C34: GRAND TOTAL | D34: =SUM(D31:D33) -> 0
A35: Notes/Assumptions
A38: Fringe applied to direct labor cost
A40: Overhead applied to Labor plus Fringe
A42: G&A applied to all costs (excluding G&A and fee)

Sheet Total Estimate
A2: Period | B2: Estimated cost | C2: Fixed Fee | D2: Estimated Cost Plus Fixed Fee | E2: Level of Effort (LOE)
A3: Base Period | B3: ='Exec Summary'!D15 -> 0 | C3: =B3*Rates!$F$9 -> 0 | D3: =SUM(B3:C3) -> 0 | E3: =SUMMARY!$B$78 -> 0
A4: Option Period 1 | B4: =B3*(1+Rates!$F$10) -> 0 | C4: =B4*Rates!$F$9 -> 0 | D4: =SUM(B4:C4) -> 0 | E4: =SUMMARY!$B$78 -> 0
A5: Option Period 2 | B5: =B4*(1+Rates!$F$10) -> 0 | C5: =B5*Rates!$F$9 -> 0 | D5: =SUM(B5:C5) -> 0 | E5: =SUMMARY!$B$78 -> 0
A6: Option Period 3 | B6: =B5*(1+Rates!$F$10) -> 0 | C6: =B6*Rates!$F$9 -> 0 | D6: =SUM(B6:C6) -> 0 | E6: =SUMMARY!$B$78 -> 0
A7: Option Period 4 | B7: =B6*(1+Rates!$F$10) -> 0 | C7: =B7*Rates!$F$9 -> 0 | D7: =SUM(B7:C7) -> 0 | E7: =SUMMARY!$B$78 -> 0
A8: Option Period 5 | B8: =B7*(1+Rates!$F$10) -> 0 | C8: =B8*Rates!$F$9 -> 0 | D8: =SUM(B8:C8) -> 0 | E8: =SUMMARY!$B$78 -> 0
A9: Option Period 6 | B9: =B8*(1+Rates!$F$10) -> 0 | C9: =B9*Rates!$F$9 -> 0 | D9: =SUM(B9:C9) -> 0 | E9: =SUMMARY!$B$78 -> 0
A10: Option Period 7 | B10: =B9*(1+Rates!$F$10) -> 0 | C10: =B10*Rates!$F$9 -> 0 | D10: =SUM(B10:C10) -> 0 | E10: =SUMMARY!$B$78 -> 0
A11: Option Period 8 | B11: =B10*(1+Rates!$F$10) -> 0 | C11: =B11*Rates!$F$9 -> 0 | D11: =SUM(B11:C11) -> 0 | E11: =SUMMARY!$B$78 -> 0
A12: Option Period 9 | B12: =B11*(1+Rates!$F$10) -> 0 | C12: =B12*Rates!$F$9 -> 0 | D12: =SUM(B12:C12) -> 0 | E12: =SUMMARY!$B$78 -> 0
A13: Optional 6-month Extension IAW FAR 52.217-8 | B13: =SUM(B12+B24)*0.5 -> 0 | C13: =B13*Rates!$F$9 -> 0 | D13: =SUM(B13:C13) -> 0 | E13: =SUM(E12+E24)*0.5 -> 0
A14: Period - Optional LOE Increase | B14: Estimated cost | C14: Fixed Fee | D14: Estimated Cost Plus Fixed Fee | E14: Level of Effort (LOE)
A15: Base Period | B15: ='Exec Summary'!G15 -> 0 | C15: =B15*Rates!$F$9 -> 0 | D15: =SUM(B15:C15) -> 0 | E15: =SUMMARY!$B$93 -> 0
A16: Option Period 1 | B16: =B15*(1+Rates!$F$10) -> 0 | C16: =B16*Rates!$F$9 -> 0 | D16: =SUM(B16:C16) -> 0 | E16: =SUMMARY!$B$93 -> 0
A17: Option Period 2 | B17: =B16*(1+Rates!$F$10) -> 0 | C17: =B17*Rates!$F$9 -> 0 | D17: =SUM(B17:C17) -> 0 | E17: =SUMMARY!$B$93 -> 0
A18: Option Period 3 | B18: =B17*(1+Rates!$F$10) -> 0 | C18: =B18*Rates!$F$9 -> 0 | D18: =SUM(B18:C18) -> 0 | E18: =SUMMARY!$B$93 -> 0
A19: Option Period 4 | B19: =B18*(1+Rates!$F$10) -> 0 | C19: =B19*Rates!$F$9 -> 0 | D19: =SUM(B19:C19) -> 0 | E19: =SUMMARY!$B$93 -> 0
A20: Option Period 5 | B20: =B19*(1+Rates!$F$10) -> 0 | C20: =B20*Rates!$F$9 -> 0 | D20: =SUM(B20:C20) -> 0 | E20: =SUMMARY!$B$93 -> 0
A21: Option Period 6 | B21: =B20*(1+Rates!$F$10) -> 0 | C21: =B21*Rates!$F$9 -> 0 | D21: =SUM(B21:C21) -> 0 | E21: =SUMMARY!$B$93 -> 0
A22: Option Period 7 | B22: =B21*(1+Rates!$F$10) -> 0 | C22: =B22*Rates!$F$9 -> 0 | D22: =SUM(B22:C22) -> 0 | E22: =SUMMARY!$B$93 -> 0
A23: Option Period 8 | B23: =B22*(1+Rates!$F$10) -> 0 | C23: =B23*Rates!$F$9 -> 0 | D23: =SUM(B23:C23) -> 0 | E23: =SUMMARY!$B$93 -> 0
A24: Option Period 9 | B24: =B23*(1+Rates!$F$10) -> 0 | C24: =B24*Rates!$F$9 -> 0 | D24: =SUM(B24:C24) -> 0 | E24: =SUMMARY!$B$93 -> 0
A25: Total Base Period and All Options | B25: =SUM(B3:B13,B15:B24) -> 0 | C25: =SUM(C3:C13,C15:C24) -> 0 | D25: =SUM(D3:D13,D15:D24) -> 0 | E25: =SUM(E3:E13,E15:E24) -> 0
